So far we've only dealt with expected errors. For example, if you want to fetch an endpoint, you would do something along these lines:

```ts
class HttpRequestError extends Data.TaggedError("HttpRequestError")<{
  readonly reason: "no-internet-connection" | "invalid-url" | "timeout" | "unknown"
}> {}

class HttpResponseError extends Data.TaggedError("HttpResponseError")<{
  readonly status?: number;
  readonly message?: string;
}> {}

const fetchTodos = pipe(
  Effect.tryPromise({
    try: () => fetch("https://jsonplaceholder.typicode.com/todos"),
    catch: (error: unknown) => {
      if (error instanceof TypeError) {
        if (error.message.includes("Failed to fetch")) {
          return new HttpRequestError({ reason: "no-internet-connection" });
        } else if (error.message.includes("URL is invalid")) {
          return new HttpRequestError({ reason: "invalid-url" });
        }
      } else if (error instanceof DOMException && error.name === "AbortError") {
        return new HttpRequestError({ reason: "timeout" });
      }
      return new HttpRequestError({ reason: "unknown" });
    },
  }),
  Effect.filterOrElse(
    (response) => response.ok,
    (response) => Effect.fail(new HttpResponseError({ status: response.status }))
  ),
  Effect.flatMap((response) =>
    Effect.tryPromise({
      try: (): Promise<unknown> => response.json(),
      catch: () => new HttpResponseError({ message: "Failed to parse todos" }),
    })
  )
);
```

This isn't particularly the best error handling possible, but notice how we're dealing with expected errors. The result type of `fetchTodos` is:

```ts
const fetchTodos: Effect.Effect<unknown, HttpRequestError | HttpResponseError, never>
```

Both, `HttpRequestError` and `HttpResponseError` are _expected_ errors, and so they are present at the type-level.

But, what if you get an unexpected error? For demonstration purposes, let's assume we are certain `fetch` cannot fail, so we use `Effect.promise`:

```ts
const program = Effect.promise(() => fetch("some-url"));
```

We obviously know that it can result in a plethora of errors, but right off the bat, we know that it will throw an "URL is invalid" error. What happens if we run this program?

```ts
Effect.runPromise(program);
```

We get a `FiberFailure`:

```ts
(FiberFailure) TypeError: fetch() URL is invalid
```

This error is **not** present at the type level:

```ts
Effect.Effect<Response, never, never>
```

If we tried recovering from it using `catchAll`, it won't work:

```ts
const program = pipe(
  Effect.promise(() => fetch("some-url")),
  Effect.catchAll(() => Effect.void)
);

Effect.runPromise(program);
```

We still get:

```ts
(FiberFailure) TypeError: fetch() URL is invalid
```

This is because `catchAll` is meant to catch **expected** errors.

If you want to catch unexpected errors, you need to use `catchAllCause`:

```ts
import { pipe, Cause, Effect } from "effect";

const program = pipe(
  Effect.promise(() => fetch("some-url")),
  Effect.catchAllCause((cause) => Effect.log(Cause.pretty(cause)}))
);

Effect.runPromise(program);
```

As we can see, this now logs the error:

```
timestamp=2024-07-13T16:45:55.811Z level=INFO fiber=#0 message="Error: TypeError: fetch() URL is invalid
```

## Logging all Errors

Let's say you want to create a utility function that logs all errors. For that, you can do something along these lines:

```ts
const logAllErrors = <A, E, R>(effect: Effect.Effect<A, E, R>): Effect.Effect<A, E, R> =>
  effect.pipe(
    Effect.tapDefect((defect) => Console.error(`Unexpected Error: ${Cause.pretty(defect)}`)),
    Effect.tapError((error) => Console.error("Expected Error", error))
  );

const program = pipe(
  Effect.promise(() => fetch("some-url")),
  logAllErrors
);

Effect.runPromise(program);
```

`tapDefect` taps into unexpected errors.